Workbook

Sheet Primary Compset comparison
A1: Competitive Set Analysis
A3: Hotel Name: Grand Millennium Dubai
A4: Date of Update:
A5: Update By:
A6: Set info:
A8: An image of the proposed set results from CoSTAR - sample below
A30: Hotel Name | B30: Grand Millennium Dubai | D30: Zabeel House The Greens by Jumeirah | F30: Radisson Blue Hotel, Dubai Media City | H30: Media One Hotel Dubai | J30: voco Bonnington Dubai | L30: Oaks Hotels & Resorts Ibn Batuta Gate Dubai
A32: Image/Rendering | B32: Hotel image | D32: Hotel image | F32: Hotel image | H32: Hotel image | J32: Hotel image | L32: Hotel image
A33: Address | B33: P.O. Box 212422 Sheikh Zayed Road - Exit 36, Barsha Heights, United Arab Emirates | D33: P.O. Box 214362 Sheikh Zayed Road, Dubai, United Arab Emirates | F33: P.O. Box 211723 Al Falak Street,Dubai Media City,Dubai,United Arab Emirates | H33: P.O. Box 121818 Al Falak Street,Dubai Media City,Dubai,United Arab Emirates | J33: P.O. Box 37246 Jumeirah Lakes Towers(JLT),Dubai,United Arab Emirates | L33: P.O. Box 211508 Garden Cross Road oppossite IBN Batuta Mall,Dubai,United Arab Emirates
A34: Distance from Hotel (KM) | B34: 0 | D34: 2.1 km | F34: 4.1 km | H34: 5.8 km | J34: 8.7 km | L34: 12.1 km
A35: Property Type (City/Resort/Beach/Landmark/Shopping/Exhibition) | B35: City | D35: City | F35: City | H35: City | J35: City | L35: City
A36: REVIEW SCORE
A37: Booking.com | B37: 9.1 | D37: 8.9 | F37: 8 | H37: 8.8 | J37: 8.9 | L37: 9
A38: Tripadvisor | B38: 4.6 | D38: 4.7 | F38: 4.5 | H38: 4.5 | J38: 4.6 | L38: 4.7
A39: Tripadvisor position | B39: 52 | D39: 173 | F39: 362 | H39: 72 | J39: 34 | L39: 169
A40: Facebook | B40: 44K followers | D40: 2.9K followers | F40: 58K followers | H40: 36K followers | J40: 66K followers | L40: 5.2K followers
A41: Brand
A42: OVERVIEW
A43: Classification/Star Rating | B43: 5 Star | D43: 4 Star | F43: 4 Star | H43: 4 Star | J43: 5 Star | L43: 5 Star
A44: Opening Year | B44: 2008 | D44: 2018 | F44: 2006 | H44: 2009 | J44: 2010 | L44: 2010
A45: Last Renovation | B45: 2014 | D45: none | F45: none | H45: 2019 | J45: 2019 | L45: 2020
A46: Affiliation | B46: Millennium Hotels and Resorts | D46: Jumeirah Group | F46: Radisson Hotel Group | H46: no affiliaton/ privately owned property | J46: InterContinental Hotels Group (IHG) | L46: Minor Hotels
A47: Owning Company/Management | B47: RTS Investments Group | D47: The Onyx for Development | F47: Select M City Ltd | H47: Al Jaber Group | J47: Arzan Investment Management | L47: Seven Tides
A48: Licensed for Alcohol (Y/N)
A49: Licensed for Shisha (Y/N)
A50: STR Rating
A51: ROOMS
A52: Total Number of Keys | B52: Total Hotel Inventory | D52: Total Hotel Inventory | F52: Total Hotel Inventory | H52: Total Hotel Inventory | J52: Total Hotel Inventory | L52: Total Hotel Inventory
A53: Type of Hotel (Rooms, All Suites, Appartments, Mixed, Condos) - State all applicable | B53: Mixed (Rooms + Apartments) | D53: Mixed (Rooms + Apartments) | F53: Mixed (Rooms + Suites) | H53: Mixed (Rooms + Suites) | J53: Mixed (Rooms + Suites) | L53: Mixed (Rooms + Apartments)
A54: Room Types/Inventory: List all room types stating size and inventory (Map similar products on the same line) | B54: Room Type/Sqm | C54: Inventory | D54: Room Class/Sqm | E54: Inventory | F54: Room Class/Sqm | G54: Inventory | H54: Room Class/Sqm | I54: Inventory | J54: Room Class/Sqm | K54: Inventory | L54: Room Class/Sqm | M54: Inventory
B55: Superior King Room (33sqm) | C55: 72 | D55: Popular Room (28sqm) | F55: Superior Room (26sqm) | H55: Standard Double Room(30sqm) | J55: Standard King Room (28sqm) | L55: Premier Room(35sqm)
B56: Deluxe King Room (33sqm) | C56: 40 | D56: Popular Room Plus (32sqm) | F56: Premium Room (32sqm) | H56: Classic Double Room with Balcony (30sqm) | J56: Deluxe King Room (35sqm) | L56: Deluxe Room (45sqm)
B57: Club Room (33sqm) | C57: 24 | D57: Popular Balcony Room(38sqm) | F57: Executive Room Lounge Access (32sqm) | H57: Classic Double Room with Palm View (30sqm) | J57: Premiium King Room with High Floor (36sqm) | L57: Executive Room 35sqm)
B58: Studio Apartment (54sqm) | C58: 20 | D58: Studio (34sqm) | F58: Executive Room with Balcony (32sqm) | H58: Executive Room (35sqm) | J58: King Suite (60sqm) | L58: One Bedroom Suite (60sqm)
B59: Business Suite (58sqm) | C59: 32 | D59: The Apartment (54sqm) | F59: One Bedroom Suite with Lounge (64sqm) | H59: Junior Suite (50sqm) | J59: Executive Suite (60sqm) | L59: Battuta Suite (85sqm)
B60: Executive Suite ( 65sqm) | C60: 34 | D60: Family Room (60sqm) | F60: Total | G60: 246 | H60: Chill Out Suite (70sqm) | J60: Total | K60: 208 | L60: Two Bedroom Apartment (95sqm)
B61: One Bedroom Apartment (94sqm) | C61: 72 | D61: Two Bedroom Family Room (86sqm) | H61: Total | I61: 264 | L61: Family Suite (70sqm)
B62: Family Suite Apartment (94sqm) | C62: 10 | L62: Deluxe Two Bedroom Apartment (122sqm)
B63: Two Bedroom Apartment (111sqm) | C63: 33 | L63: Total | M63: 411
B64: Royal Suite | C64: 1 | D64: Total | E64: 210
...

Sheet Business Mix & Overalp Analysis
A1: Competitive Set Analysis
A3: Hotel Name: Grand Millennium Dubai
A4: Date of Update:
A5: Update By:
A6: Set info:
A8: Competition Set Selection Process - Business Mix & Competition Overlap Analysis
A10: Step 1- Business Mix Survey | B10: Business Mix %
A11: Competitor Hotel Name | B11: Transient | C11: Corporate Business FIT | D11: Wholesale FIT | E11: Groups Conv & Meetings | F11: Groups Leisure | G11: long term | H11: Total Bus Mix%
A12: Grand Millennium Dubai | H12: =SUM(B12:G12) -> 0
A13: Zabeel House The Greens by Jumeirah | H13: =SUM(B13:G13) -> 0
A14: Radisson Blue Hotel, Dubai Media City | H14: =SUM(B14:G14) -> 0
A15: Media One Hotel Dubai | H15: =SUM(B15:G15) -> 0
A16: voco Bonnington Dubai | H16: =SUM(B16:G16) -> 0
A17: Oaks Hotels & Resorts Ibn Batuta Gate Dubai | H17: =SUM(B17:G17) -> 0
H18: =SUM(B18:G18) -> 0
A21: Step 2-Competitiveness Survey | B21: Business Overlap %
A22: Competitor Hotel Name | B22: Transient | C22: Corporate Business FIT | D22: Wholesale FIT | E22: Groups Conv & Meetings | F22: Groups Leisure | G22: long term
A23: =A13 -> Zabeel House The Greens by Jumeirah
A24: =A14 -> Radisson Blue Hotel, Dubai Media City
A25: =A15 -> Media One Hotel Dubai
A26: =A16 -> voco Bonnington Dubai
A27: =A17 -> Oaks Hotels & Resorts Ibn Batuta Gate Dubai
A28: =A18 -> 0
A31: Overlapping Buisness Mix | B31: Competitiveness %
A32: Competitor Hotel Name | B32: Transient | C32: Corporate Business FIT | D32: Wholesale FIT | E32: Groups Conv & Meetings | F32: Groups Leisure | G32: long term | H32: Overall Competitiveness Score
A33: =A13 -> Zabeel House The Greens by Jumeirah | B33: =B13*B23/100 -> 0 | C33: =C13*C23/100 -> 0 | D33: =D13*D23/100 -> 0 | E33: =E13*E23/100 -> 0 | F33: =F13*F23/100 -> 0 | G33: =G13*G23/100 -> 0 | H33: =SUM(B33:G33) -> 0
A34: =A14 -> Radisson Blue Hotel, Dubai Media City | B34: =B14*B24/100 -> 0 | C34: =C14*C24/100 -> 0 | D34: =D14*D24/100 -> 0 | E34: =E14*E24/100 -> 0 | F34: =F14*F24/100 -> 0 | G34: =G14*G24/100 -> 0 | H34: =SUM(B34:G34) -> 0
A35: =A15 -> Media One Hotel Dubai | B35: =B15*B25/100 -> 0 | C35: =C15*C25/100 -> 0 | D35: =D15*D25/100 -> 0 | E35: =E15*E25/100 -> 0 | F35: =F15*F25/100 -> 0 | G35: =G15*G25/100 -> 0 | H35: =SUM(B35:G35) -> 0
A36: =A16 -> voco Bonnington Dubai | B36: =B16*B26/100 -> 0 | C36: =C16*C26/100 -> 0 | D36: =D16*D26/100 -> 0 | E36: =E16*E26/100 -> 0 | F36: =F16*F26/100 -> 0 | G36: =G16*G26/100 -> 0 | H36: =SUM(B36:G36) -> 0
A37: =A17 -> Oaks Hotels & Resorts Ibn Batuta Gate Dubai | B37: =B17*B27/100 -> 0 | C37: =C17*C27/100 -> 0 | D37: =D17*D27/100 -> 0 | E37: =E17*E27/100 -> 0 | F37: =F17*F27/100 -> 0 | G37: =G17*G27/100 -> 0 | H37: =SUM(B37:G37) -> 0
A38: =A18 -> 0 | B38: =B18*B28/100 -> 0 | C38: =C18*C28/100 -> 0 | D38: =D18*D28/100 -> 0 | E38: =E18*E28/100 -> 0 | F38: =F18*F28/100 -> 0 | G38: =G18*G28/100 -> 0 | H38: =SUM(B38:G38) -> 0
B40: Move to Value Proposition Tab

Sheet Value Proposition
A1: Competitive Set Analysis
A3: Hotel Name: Grand Millennium Dubai
A4: Date of Update:
A5: Update By:
A6: Set info:
A10: Competition Set Selection Process - Value Proposition Analysis
A12: Step 4-Competitive Rate Analysis | B12: Rate Comparison - Normal Season
A13: Competitor Hotel Name | B13: Transient | C13: Corporate Business FIT | D13: Wholesale FIT | E13: Groups Conv & Meetings | F13: Groups Leisure | G13: long term
A14: ='Business Mix & Overalp Analysis'!A12 -> Grand Millennium Dubai
A15: ='Business Mix & Overalp Analysis'!A13 -> Zabeel House The Greens by Jumeirah
A16: ='Business Mix & Overalp Analysis'!A14 -> Radisson Blue Hotel, Dubai Media City
A17: ='Business Mix & Overalp Analysis'!A15 -> Media One Hotel Dubai
A18: ='Business Mix & Overalp Analysis'!A16 -> voco Bonnington Dubai
A19: ='Business Mix & Overalp Analysis'!A17 -> Oaks Hotels & Resorts Ibn Batuta Gate Dubai
A20: ='Business Mix & Overalp Analysis'!A18 -> 0
A23: Step 5-Weighted Rate Analysis | B23: Weighted Rate Comparison - Normal Season
A24: Competitor Hotel Name | B24: Transient | C24: Corporate Business FIT | D24: Wholesale FIT | E24: Groups Conv & Meetings | F24: Groups Leisure | G24: long term | H24: Weighted Total Avg Rate
A25: =A14 -> Grand Millennium Dubai | B25: =B14*'Business Mix & Overalp Analysis'!B12/100 -> 0 | C25: =C14*'Business Mix & Overalp Analysis'!C12/100 -> 0 | D25: =D14*'Business Mix & Overalp Analysis'!D12/100 -> 0 | E25: =E14*'Business Mix & Overalp Analysis'!E12/100 -> 0 | F25: =F14*'Business Mix & Overalp Analysis'!F12/100 -> 0 | G25: =G14*'Business Mix & Overalp Analysis'!G12/100 -> 0 | H25: =SUM(B25:G25) -> 0
A26: =A15 -> Zabeel House The Greens by Jumeirah | B26: =B15*'Business Mix & Overalp Analysis'!B13/100 -> 0 | C26: =C15*'Business Mix & Overalp Analysis'!C13/100 -> 0 | D26: =D15*'Business Mix & Overalp Analysis'!D13/100 -> 0 | E26: =E15*'Business Mix & Overalp Analysis'!E13/100 -> 0 | F26: =F15*'Business Mix & Overalp Analysis'!F13/100 -> 0 | G26: =G15*'Business Mix & Overalp Analysis'!G13/100 -> 0 | H26: =SUM(B26:G26) -> 0
A27: =A16 -> Radisson Blue Hotel, Dubai Media City | B27: =B16*'Business Mix & Overalp Analysis'!B14/100 -> 0 | C27: =C16*'Business Mix & Overalp Analysis'!C14/100 -> 0 | D27: =D16*'Business Mix & Overalp Analysis'!D14/100 -> 0 | E27: =E16*'Business Mix & Overalp Analysis'!E14/100 -> 0 | F27: =F16*'Business Mix & Overalp Analysis'!F14/100 -> 0 | G27: =G16*'Business Mix & Overalp Analysis'!G14/100 -> 0 | H27: =SUM(B27:G27) -> 0
A28: =A17 -> Media One Hotel Dubai | B28: =B17*'Business Mix & Overalp Analysis'!B15/100 -> 0 | C28: =C17*'Business Mix & Overalp Analysis'!C15/100 -> 0 | D28: =D17*'Business Mix & Overalp Analysis'!D15/100 -> 0 | E28: =E17*'Business Mix & Overalp Analysis'!E15/100 -> 0 | F28: =F17*'Business Mix & Overalp Analysis'!F15/100 -> 0 | G28: =G17*'Business Mix & Overalp Analysis'!G15/100 -> 0 | H28: =SUM(B28:G28) -> 0
A29: =A18 -> voco Bonnington Dubai | B29: =B18*'Business Mix & Overalp Analysis'!B16/100 -> 0 | C29: =C18*'Business Mix & Overalp Analysis'!C16/100 -> 0 | D29: =D18*'Business Mix & Overalp Analysis'!D16/100 -> 0 | E29: =E18*'Business Mix & Overalp Analysis'!E16/100 -> 0 | F29: =F18*'Business Mix & Overalp Analysis'!F16/100 -> 0 | G29: =G18*'Business Mix & Overalp Analysis'!G16/100 -> 0 | H29: =SUM(B29:G29) -> 0
A30: =A19 -> Oaks Hotels & Resorts Ibn Batuta Gate Dubai | B30: =B19*'Business Mix & Overalp Analysis'!B17/100 -> 0 | C30: =C19*'Business Mix & Overalp Analysis'!C17/100 -> 0 | D30: =D19*'Business Mix & Overalp Analysis'!D17/100 -> 0 | E30: =E19*'Business Mix & Overalp Analysis'!E17/100 -> 0 | F30: =F19*'Business Mix & Overalp Analysis'!F17/100 -> 0 | G30: =G19*'Business Mix & Overalp Analysis'!G17/100 -> 0 | H30: =SUM(B30:G30) -> 0
A31: ='Business Mix & Overalp Analysis'!A18 -> 0 | B31: =B20*'Business Mix & Overalp Analysis'!B18/100 -> 0 | C31: =C20*'Business Mix & Overalp Analysis'!C18/100 -> 0 | D31: =D20*'Business Mix & Overalp Analysis'!D18/100 -> 0 | E31: =E20*'Business Mix & Overalp Analysis'!E18/100 -> 0 | F31: =F20*'Business Mix & Overalp Analysis'!F18/100 -> 0 | G31: =G20*'Business Mix & Overalp Analysis'!G18/100 -> 0 | H31: =SUM(B31:G31) -> 0
A33: Step 6-Quality Analysis | B33: TripAdvisor & Brand - (rating from 1 to 10) | I33: (Booking.com) Quality Comparison | Q33: Trip Advisor Ranking
A34: Competitor Hotel Name | B34: Guestroom | C34: F&B | D34: Meeting Facilities | E34: Leisure Facilities | F34: Staff (Attitude + Knowledge) | G34: Technology | H34: Average Quality Rating | I34: Cleanliness | J34: Location | K34: Staff | L34: Free Wifi | M34: Comfort | N34: Facilities | O34: Value For Money | P34: Average Quality Rating
A35: =A25 -> Grand Millennium Dubai | H35: =AVERAGE(B35:G35) -> #DIV/0!
A36: =A26 -> Zabeel House The Greens by Jumeirah | H36: =AVERAGE(B36:G36) -> #DIV/0!
A37: =A27 -> Radisson Blue Hotel, Dubai Media City | H37: =AVERAGE(B37:G37) -> #DIV/0!
A38: =A28 -> Media One Hotel Dubai | H38: =AVERAGE(B38:G38) -> #DIV/0!
A39: =A29 -> voco Bonnington Dubai | H39: =AVERAGE(B39:G39) -> #DIV/0!
A40: =A30 -> Oaks Hotels & Resorts Ibn Batuta Gate Dubai | H40: =AVERAGE(B40:G40) -> #DIV/0!
A41: ='Business Mix & Overalp Analysis'!A18 -> 0 | H41: =AVERAGE(B41:G41) -> #DIV/0! | P41: =AVERAGE(I41:O41) -> #DIV/0! | Q41: 0
A44: Step 7-Value Proposition / Grid | B44: Value Elements
A45: Competitor Hotel Name | B45: Weighted Total Avg Rate | C45: Average Quality Rating | D45: Rate Index | E45: Quality Index | F45: Total
A46: Millennium Hotel Name | B46: =H25 -> 0 | C46: =(H35*0.3)+(P35*0.5)+(Q35/AVERAGE($Q$35:$Q$41)*0.2) -> #DIV/0! | D46: =(B46/$B$53-1)*100 -> #DIV/0! | E46: =(C46/ABS($C$53)-1)*100 -> #DIV/0! | F46: =(E46*0.7)+(D46*0.3) -> #DIV/0!
A47: Competitor Hotel Name 1 | B47: =H26 -> 0 | C47: =(H36*0.3)+(P36*0.5)+(Q36/AVERAGE($Q$35:$Q$41)*0.2) -> #DIV/0! | D47: =(B47/$B$53-1)*100 -> #DIV/0! | E47: =(C47/ABS($C$53)-1)*100 -> #DIV/0! | F47: =(E47*0.7)+(D47*0.3) -> #DIV/0!
A48: Competitor Hotel Name 2 | B48: =H27 -> 0 | C48: =(H37*0.3)+(P37*0.5)+(Q37/AVERAGE($Q$35:$Q$41)*0.2) -> #DIV/0! | D48: =(B48/$B$53-1)*100 -> #DIV/0! | E48: =(C48/ABS($C$53)-1)*100 -> #DIV/0! | F48: =(E48*0.7)+(D48*0.3) -> #DIV/0!
A49: Competitor Hotel Name 3 | B49: =H28 -> 0 | C49: =(H38*0.3)+(P38*0.5)+(Q38/AVERAGE($Q$35:$Q$41)*0.2) -> #DIV/0! | D49: =(B49/$B$53-1)*100 -> #DIV/0! | E49: =(C49/ABS($C$53)-1)*100 -> #DIV/0! | F49: =(E49*0.7)+(D49*0.3) -> #DIV/0!
A50: Competitor Hotel Name 4 | B50: =H29 -> 0 | C50: =(H39*0.3)+(P39*0.5)+(Q39/AVERAGE($Q$35:$Q$41)*0.2) -> #DIV/0! | D50: =(B50/$B$53-1)*100 -> #DIV/0! | E50: =(C50/ABS($C$53)-1)*100 -> #DIV/0! | F50: =(E50*0.7)+(D50*0.3) -> #DIV/0!
...

Sheet RPM
A1: Post RPMs for the past 12 M this year and last year

Sheet Bandwidth
A1: Post three set of Bandwidth each from a different season {ie ending August for summer reflection// April for Q1 reflectiom // Oct for Q4 reflection - choose periods that reflect your property's unique seasonality and most impactful dates}
